Workbook

Sheet TONG_HOP
A1: Bảng TH Chênh Lệch Từ Tháng 5 Đến tháng 5/2026 | E1: CHÊNH LỆCH | I1: Bảng CT Chênh Lệch Từ Tháng 5 Đến tháng 5/2026 | M1: CHÊNH LỆCH
A2: {=VLOOKUP(INDEX(DSDVI!$D$2:$D$25,MATCH(TRUE,DSDVI!D2:D25<>"",0)),DSDVI!$A$2:$C$25,2,0)} -> HCMC - Công ty Điện lực Vũng Tàu | I2: {=VLOOKUP(INDEX(DSDVI!$D$2:$D$25,MATCH(TRUE,DSDVI!$D$2:$D$25<>"",0)),DSDVI!$A$2:$C$25,2,0)} -> HCMC - Công ty Điện lực Vũng Tàu
A3: 1363111 | B3: 3363111 | C3: =SUMIFS(DATA_TONGHOP!N:N,DATA_TONGHOP!C:C,"080100",DATA_TONGHOP!A:A,TONG_HOP!A3) -> -934199717138 | D3: {=SUMIFS(DATA_TONGHOP!N:N,DATA_TONGHOP!C:C,INDEX(DSDVI!$D$2:$D$25,MATCH(TRUE,DSDVI!$D$2:$D$25<>"",0)),DATA_TONGHOP!A:A,TONG_HOP!B3)} -> 488183646170 | E3: =IF(C3-D3=0,0,HYPERLINK("#'"&A3&"_"&B3&"'!A1",C3-D3)) -> -1422383363308 | I3: 1363111 | J3: 3363111 | K3: =SUMIFS(DATA_PHATSINH!T:T,DATA_PHATSINH!M:M,"080100",DATA_PHATSINH!A:A,TONG_HOP!I3) -> -1361722492155 | L3: {=SUMIFS(DATA_PHATSINH!T:T,DATA_PHATSINH!M:M,INDEX(DSDVI!$D$2:$D$25,MATCH(TRUE,DSDVI!$D$2:$D$25<>"",0)),DATA_PHATSINH!A:A,TONG_HOP!J3)} -> 60660871153 | M3: =IF(K3-L3=0,0,HYPERLINK("#'"&A3&"_"&B3&"'!A1",K3-L3)) -> -1422383363308
A4: 1363112 | B4: 3363112 | C4: =SUMIFS(DATA_TONGHOP!N:N,DATA_TONGHOP!C:C,"080100",DATA_TONGHOP!A:A,TONG_HOP!A4) -> -4548652836 | D4: {=SUMIFS(DATA_TONGHOP!N:N,DATA_TONGHOP!C:C,INDEX(DSDVI!$D$2:$D$25,MATCH(TRUE,DSDVI!$D$2:$D$25<>"",0)),DATA_TONGHOP!A:A,TONG_HOP!B4)} -> -3876382947 | E4: =IF(C4-D4=0,0,HYPERLINK("#'"&A4&"_"&B4&"'!A1",C4-D4)) -> -672269889 | I4: 1363112 | J4: 3363112 | K4: =SUMIFS(DATA_PHATSINH!T:T,DATA_PHATSINH!M:M,"080100",DATA_PHATSINH!A:A,TONG_HOP!I4) -> -641017536 | L4: {=SUMIFS(DATA_PHATSINH!T:T,DATA_PHATSINH!M:M,INDEX(DSDVI!$D$2:$D$25,MATCH(TRUE,DSDVI!$D$2:$D$25<>"",0)),DATA_PHATSINH!A:A,TONG_HOP!J4)} -> 31252353 | M4: =IF(K4-L4=0,0,HYPERLINK("#'"&A4&"_"&B4&"'!A1",K4-L4)) -> -672269889
A5: 136312 | B5: 336312 | C5: =SUMIFS(DATA_TONGHOP!N:N,DATA_TONGHOP!C:C,"080100",DATA_TONGHOP!A:A,TONG_HOP!A5) -> 0 | D5: {=SUMIFS(DATA_TONGHOP!N:N,DATA_TONGHOP!C:C,INDEX(DSDVI!$D$2:$D$25,MATCH(TRUE,DSDVI!$D$2:$D$25<>"",0)),DATA_TONGHOP!A:A,TONG_HOP!B5)} -> 0 | E5: =IF(C5-D5=0,0,HYPERLINK("#'"&A5&"_"&B5&"'!A1",C5-D5)) -> 0 | I5: 136312 | J5: 336312 | K5: =SUMIFS(DATA_PHATSINH!T:T,DATA_PHATSINH!M:M,"080100",DATA_PHATSINH!A:A,TONG_HOP!I5) -> 0 | L5: {=SUMIFS(DATA_PHATSINH!T:T,DATA_PHATSINH!M:M,INDEX(DSDVI!$D$2:$D$25,MATCH(TRUE,DSDVI!$D$2:$D$25<>"",0)),DATA_PHATSINH!A:A,TONG_HOP!J5)} -> 0 | M5: =IF(K5-L5=0,0,HYPERLINK("#'"&A5&"_"&B5&"'!A1",K5-L5)) -> 0
A6: 136313 | B6: 336313 | C6: =SUMIFS(DATA_TONGHOP!N:N,DATA_TONGHOP!C:C,"080100",DATA_TONGHOP!A:A,TONG_HOP!A6) -> 0 | D6: {=SUMIFS(DATA_TONGHOP!N:N,DATA_TONGHOP!C:C,INDEX(DSDVI!$D$2:$D$25,MATCH(TRUE,DSDVI!$D$2:$D$25<>"",0)),DATA_TONGHOP!A:A,TONG_HOP!B6)} -> 0 | E6: =IF(C6-D6=0,0,HYPERLINK("#'"&A6&"_"&B6&"'!A1",C6-D6)) -> 0 | I6: 136313 | J6: 336313 | K6: =SUMIFS(DATA_PHATSINH!T:T,DATA_PHATSINH!M:M,"080100",DATA_PHATSINH!A:A,TONG_HOP!I6) -> 0 | L6: {=SUMIFS(DATA_PHATSINH!T:T,DATA_PHATSINH!M:M,INDEX(DSDVI!$D$2:$D$25,MATCH(TRUE,DSDVI!$D$2:$D$25<>"",0)),DATA_PHATSINH!A:A,TONG_HOP!J6)} -> 0 | M6: =IF(K6-L6=0,0,HYPERLINK("#'"&A6&"_"&B6&"'!A1",K6-L6)) -> 0
A7: 136314 | B7: 336314 | C7: =SUMIFS(DATA_TONGHOP!N:N,DATA_TONGHOP!C:C,"080100",DATA_TONGHOP!A:A,TONG_HOP!A7) -> 7987850607 | D7: {=SUMIFS(DATA_TONGHOP!N:N,DATA_TONGHOP!C:C,INDEX(DSDVI!$D$2:$D$25,MATCH(TRUE,DSDVI!$D$2:$D$25<>"",0)),DATA_TONGHOP!A:A,TONG_HOP!B7)} -> 8241423967 | E7: =IF(C7-D7=0,0,HYPERLINK("#'"&A7&"_"&B7&"'!A1",C7-D7)) -> -253573360 | I7: 136314 | J7: 336314 | K7: =SUMIFS(DATA_PHATSINH!T:T,DATA_PHATSINH!M:M,"080100",DATA_PHATSINH!A:A,TONG_HOP!I7) -> 0 | L7: {=SUMIFS(DATA_PHATSINH!T:T,DATA_PHATSINH!M:M,INDEX(DSDVI!$D$2:$D$25,MATCH(TRUE,DSDVI!$D$2:$D$25<>"",0)),DATA_PHATSINH!A:A,TONG_HOP!J7)} -> 253573360 | M7: =IF(K7-L7=0,0,HYPERLINK("#'"&A7&"_"&B7&"'!A1",K7-L7)) -> -253573360
A8: 136315 | B8: 336315 | C8: =SUMIFS(DATA_TONGHOP!N:N,DATA_TONGHOP!C:C,"080100",DATA_TONGHOP!A:A,TONG_HOP!A8) -> 0 | D8: {=SUMIFS(DATA_TONGHOP!N:N,DATA_TONGHOP!C:C,INDEX(DSDVI!$D$2:$D$25,MATCH(TRUE,DSDVI!$D$2:$D$25<>"",0)),DATA_TONGHOP!A:A,TONG_HOP!B8)} -> 0 | E8: =IF(C8-D8=0,0,HYPERLINK("#'"&A8&"_"&B8&"'!A1",C8-D8)) -> 0 | I8: 136315 | J8: 336315 | K8: =SUMIFS(DATA_PHATSINH!T:T,DATA_PHATSINH!M:M,"080100",DATA_PHATSINH!A:A,TONG_HOP!I8) -> 0 | L8: {=SUMIFS(DATA_PHATSINH!T:T,DATA_PHATSINH!M:M,INDEX(DSDVI!$D$2:$D$25,MATCH(TRUE,DSDVI!$D$2:$D$25<>"",0)),DATA_PHATSINH!A:A,TONG_HOP!J8)} -> 0 | M8: =IF(K8-L8=0,0,HYPERLINK("#'"&A8&"_"&B8&"'!A1",K8-L8)) -> 0
A9: 136318 | B9: 336318 | C9: =SUMIFS(DATA_TONGHOP!N:N,DATA_TONGHOP!C:C,"080100",DATA_TONGHOP!A:A,TONG_HOP!A9) -> 0 | D9: {=SUMIFS(DATA_TONGHOP!N:N,DATA_TONGHOP!C:C,INDEX(DSDVI!$D$2:$D$25,MATCH(TRUE,DSDVI!$D$2:$D$25<>"",0)),DATA_TONGHOP!A:A,TONG_HOP!B9)} -> 0 | E9: =IF(C9-D9=0,0,HYPERLINK("#'"&A9&"_"&B9&"'!A1",C9-D9)) -> 0 | I9: 136318 | J9: 336318 | K9: =SUMIFS(DATA_PHATSINH!T:T,DATA_PHATSINH!M:M,"080100",DATA_PHATSINH!A:A,TONG_HOP!I9) -> 0 | L9: {=SUMIFS(DATA_PHATSINH!T:T,DATA_PHATSINH!M:M,INDEX(DSDVI!$D$2:$D$25,MATCH(TRUE,DSDVI!$D$2:$D$25<>"",0)),DATA_PHATSINH!A:A,TONG_HOP!J9)} -> 0 | M9: =IF(K9-L9=0,0,HYPERLINK("#'"&A9&"_"&B9&"'!A1",K9-L9)) -> 0
A10: 136321 | B10: 336321 | C10: =SUMIFS(DATA_TONGHOP!N:N,DATA_TONGHOP!C:C,"080100",DATA_TONGHOP!A:A,TONG_HOP!A10) -> 0 | D10: {=SUMIFS(DATA_TONGHOP!N:N,DATA_TONGHOP!C:C,INDEX(DSDVI!$D$2:$D$25,MATCH(TRUE,DSDVI!$D$2:$D$25<>"",0)),DATA_TONGHOP!A:A,TONG_HOP!B10)} -> 0 | E10: =IF(C10-D10=0,0,HYPERLINK("#'"&A10&"_"&B10&"'!A1",C10-D10)) -> 0 | I10: 136321 | J10: 336321 | K10: =SUMIFS(DATA_PHATSINH!T:T,DATA_PHATSINH!M:M,"080100",DATA_PHATSINH!A:A,TONG_HOP!I10) -> 0 | L10: {=SUMIFS(DATA_PHATSINH!T:T,DATA_PHATSINH!M:M,INDEX(DSDVI!$D$2:$D$25,MATCH(TRUE,DSDVI!$D$2:$D$25<>"",0)),DATA_PHATSINH!A:A,TONG_HOP!J10)} -> 0 | M10: =IF(K10-L10=0,0,HYPERLINK("#'"&A10&"_"&B10&"'!A1",K10-L10)) -> 0
A11: 136322 | B11: 336322 | C11: =SUMIFS(DATA_TONGHOP!N:N,DATA_TONGHOP!C:C,"080100",DATA_TONGHOP!A:A,TONG_HOP!A11) -> 0 | D11: {=SUMIFS(DATA_TONGHOP!N:N,DATA_TONGHOP!C:C,INDEX(DSDVI!$D$2:$D$25,MATCH(TRUE,DSDVI!$D$2:$D$25<>"",0)),DATA_TONGHOP!A:A,TONG_HOP!B11)} -> 0 | E11: =IF(C11-D11=0,0,HYPERLINK("#'"&A11&"_"&B11&"'!A1",C11-D11)) -> 0 | I11: 136322 | J11: 336322 | K11: =SUMIFS(DATA_PHATSINH!T:T,DATA_PHATSINH!M:M,"080100",DATA_PHATSINH!A:A,TONG_HOP!I11) -> 0 | L11: {=SUMIFS(DATA_PHATSINH!T:T,DATA_PHATSINH!M:M,INDEX(DSDVI!$D$2:$D$25,MATCH(TRUE,DSDVI!$D$2:$D$25<>"",0)),DATA_PHATSINH!A:A,TONG_HOP!J11)} -> 0 | M11: =IF(K11-L11=0,0,HYPERLINK("#'"&A11&"_"&B11&"'!A1",K11-L11)) -> 0
A12: 136323 | B12: 336323 | C12: =SUMIFS(DATA_TONGHOP!N:N,DATA_TONGHOP!C:C,"080100",DATA_TONGHOP!A:A,TONG_HOP!A12) -> 0 | D12: {=SUMIFS(DATA_TONGHOP!N:N,DATA_TONGHOP!C:C,INDEX(DSDVI!$D$2:$D$25,MATCH(TRUE,DSDVI!$D$2:$D$25<>"",0)),DATA_TONGHOP!A:A,TONG_HOP!B12)} -> 0 | E12: =IF(C12-D12=0,0,HYPERLINK("#'"&A12&"_"&B12&"'!A1",C12-D12)) -> 0 | I12: 136323 | J12: 336323 | K12: =SUMIFS(DATA_PHATSINH!T:T,DATA_PHATSINH!M:M,"080100",DATA_PHATSINH!A:A,TONG_HOP!I12) -> 0 | L12: {=SUMIFS(DATA_PHATSINH!T:T,DATA_PHATSINH!M:M,INDEX(DSDVI!$D$2:$D$25,MATCH(TRUE,DSDVI!$D$2:$D$25<>"",0)),DATA_PHATSINH!A:A,TONG_HOP!J12)} -> 0 | M12: =IF(K12-L12=0,0,HYPERLINK("#'"&A12&"_"&B12&"'!A1",K12-L12)) -> 0
A13: 136331 | B13: 336331 | C13: =SUMIFS(DATA_TONGHOP!N:N,DATA_TONGHOP!C:C,"080100",DATA_TONGHOP!A:A,TONG_HOP!A13) -> -392951167430 | D13: {=SUMIFS(DATA_TONGHOP!N:N,DATA_TONGHOP!C:C,INDEX(DSDVI!$D$2:$D$25,MATCH(TRUE,DSDVI!$D$2:$D$25<>"",0)),DATA_TONGHOP!A:A,TONG_HOP!B13)} -> -399274041310 | E13: =IF(C13-D13=0,0,HYPERLINK("#'"&A13&"_"&B13&"'!A1",C13-D13)) -> 6322873880 | I13: 136331 | J13: 336331 | K13: =SUMIFS(DATA_PHATSINH!T:T,DATA_PHATSINH!M:M,"080100",DATA_PHATSINH!A:A,TONG_HOP!I13) -> 14964537632 | L13: {=SUMIFS(DATA_PHATSINH!T:T,DATA_PHATSINH!M:M,INDEX(DSDVI!$D$2:$D$25,MATCH(TRUE,DSDVI!$D$2:$D$25<>"",0)),DATA_PHATSINH!A:A,TONG_HOP!J13)} -> 8641663752 | M13: =IF(K13-L13=0,0,HYPERLINK("#'"&A13&"_"&B13&"'!A1",K13-L13)) -> 6322873880
A14: 136332 | B14: 336332 | C14: =SUMIFS(DATA_TONGHOP!N:N,DATA_TONGHOP!C:C,"080100",DATA_TONGHOP!A:A,TONG_HOP!A14) -> 0 | D14: {=SUMIFS(DATA_TONGHOP!N:N,DATA_TONGHOP!C:C,INDEX(DSDVI!$D$2:$D$25,MATCH(TRUE,DSDVI!$D$2:$D$25<>"",0)),DATA_TONGHOP!A:A,TONG_HOP!B14)} -> 877629907 | E14: =IF(C14-D14=0,0,HYPERLINK("#'"&A14&"_"&B14&"'!A1",C14-D14)) -> -877629907 | I14: 136332 | J14: 336332 | K14: =SUMIFS(DATA_PHATSINH!T:T,DATA_PHATSINH!M:M,"080100",DATA_PHATSINH!A:A,TONG_HOP!I14) -> 0 | L14: {=SUMIFS(DATA_PHATSINH!T:T,DATA_PHATSINH!M:M,INDEX(DSDVI!$D$2:$D$25,MATCH(TRUE,DSDVI!$D$2:$D$25<>"",0)),DATA_PHATSINH!A:A,TONG_HOP!J14)} -> 877629907 | M14: =IF(K14-L14=0,0,HYPERLINK("#'"&A14&"_"&B14&"'!A1",K14-L14)) -> -877629907
... A51: 13688 | B51: 33688 | C51: =SUMIFS(DATA_TONGHOP!N:N,DATA_TONGHOP!C:C,"080100",DATA_TONGHOP!A:A,TONG_HOP!A51) -> 0 | D51: {=SUMIFS(DATA_TONGHOP!N:N,DATA_TONGHOP!C:C,INDEX(DSDVI!$D$2:$D$25,MATCH(TRUE,DSDVI!$D$2:$D$25<>"",0)),DATA_TONGHOP!A:A,TONG_HOP!B51)} -> 0 | E51: =IF(C51-D51=0,0,HYPERLINK("#'"&A51&"_"&B51&"'!A1",C51-D51)) -> 0 | I51: 13688 | J51: 33688 | K51: =SUMIFS(DATA_PHATSINH!T:T,DATA_PHATSINH!M:M,"080100",DATA_PHATSINH!A:A,TONG_HOP!I51) -> 0 | L51: {=SUMIFS(DATA_PHATSINH!T:T,DATA_PHATSINH!M:M,INDEX(DSDVI!$D$2:$D$25,MATCH(TRUE,DSDVI!$D$2:$D$25<>"",0)),DATA_PHATSINH!A:A,TONG_HOP!J51)} -> 0 | M51: =IF(K51-L51=0,0,HYPERLINK("#'"&A51&"_"&B51&"'!A1",K51-L51)) -> 0
A52: 33688 | B52: 13688 | C52: =SUMIFS(DATA_TONGHOP!N:N,DATA_TONGHOP!C:C,"080100",DATA_TONGHOP!A:A,TONG_HOP!A52) -> 0 | D52: {=SUMIFS(DATA_TONGHOP!N:N,DATA_TONGHOP!C:C,INDEX(DSDVI!$D$2:$D$25,MATCH(TRUE,DSDVI!$D$2:$D$25<>"",0)),DATA_TONGHOP!A:A,TONG_HOP!B52)} -> 0 | E52: =IF(C52-D52=0,0,HYPERLINK("#'"&A52&"_"&B52&"'!A1",C52-D52)) -> 0 | I52: 33688 | J52: 13688 | K52: =SUMIFS(DATA_PHATSINH!T:T,DATA_PHATSINH!M:M,"080100",DATA_PHATSINH!A:A,TONG_HOP!I52) -> 0 | L52: {=SUMIFS(DATA_PHATSINH!T:T,DATA_PHATSINH!M:M,INDEX(DSDVI!$D$2:$D$25,MATCH(TRUE,DSDVI!$D$2:$D$25<>"",0)),DATA_PHATSINH!A:A,TONG_HOP!J52)} -> 0 | M52: =IF(K52-L52=0,0,HYPERLINK("#'"&A52&"_"&B52&"'!A1",K52-L52)) -> 0
A53: 3363888 | B53: 1363888 | C53: =SUMIFS(DATA_TONGHOP!N:N,DATA_TONGHOP!C:C,"080100",DATA_TONGHOP!A:A,TONG_HOP!A53) -> -338901499 | D53: {=SUMIFS(DATA_TONGHOP!N:N,DATA_TONGHOP!C:C,INDEX(DSDVI!$D$2:$D$25,MATCH(TRUE,DSDVI!$D$2:$D$25<>"",0)),DATA_TONGHOP!A:A,TONG_HOP!B53)} -> -338901499 | E53: =IF(C53-D53=0,0,HYPERLINK("#'"&A53&"_"&B53&"'!A1",C53-D53)) -> 0 | I53: 3363888 | J53: 1363888 | K53: =SUMIFS(DATA_PHATSINH!T:T,DATA_PHATSINH!M:M,"080100",DATA_PHATSINH!A:A,TONG_HOP!I53) -> -40655098 | L53: {=SUMIFS(DATA_PHATSINH!T:T,DATA_PHATSINH!M:M,INDEX(DSDVI!$D$2:$D$25,MATCH(TRUE,DSDVI!$D$2:$D$25<>"",0)),DATA_PHATSINH!A:A,TONG_HOP!J53)} -> -40655098 | M53: =IF(K53-L53=0,0,HYPERLINK("#'"&A53&"_"&B53&"'!A1",K53-L53)) -> 0
A54: 13681 | B54: 33681 | C54: {=0-SUMIFS(DATA_TONGHOP!N:N,DATA_TONGHOP!C:C,INDEX(DSDVI!$D$2:$D$25,MATCH(TRUE,DSDVI!$D$2:$D$25<>"",0)),DATA_TONGHOP!A:A,TONG_HOP!A54)} -> 14383337492 | D54: {=SUMIFS(DATA_TONGHOP!N:N,DATA_TONGHOP!C:C,INDEX(DSDVI!$D$2:$D$25,MATCH(TRUE,DSDVI!$D$2:$D$25<>"",0)),DATA_TONGHOP!A:A,TONG_HOP!B54)} -> 15100381544 | E54: =IF(C54-D54=0,0,HYPERLINK("#'"&A54&"_"&B54&"'!A1",C54-D54)) -> -717044052 | I54: 13681 | J54: 33681 | K54: {=0-SUMIFS(DATA_PHATSINH!T:T,DATA_PHATSINH!M:M,INDEX(DSDVI!$D$2:$D$25,MATCH(TRUE,DSDVI!$D$2:$D$25<>"",0)),DATA_PHATSINH!A:A,TONG_HOP!I54)} -> -138039697 | L54: {=SUMIFS(DATA_PHATSINH!T:T,DATA_PHATSINH!M:M,INDEX(DSDVI!$D$2:$D$25,MATCH(TRUE,DSDVI!$D$2:$D$25<>"",0)),DATA_PHATSINH!A:A,TONG_HOP!J54)} -> -138039697 | M54: =IF(K54-L54=0,0,HYPERLINK("#'"&A54&"_"&B54&"'!A1",K54-L54)) -> 0
C55: =SUMIFS(DATA_TONGHOP!N:N,DATA_TONGHOP!C:C,"080100",DATA_TONGHOP!A:A,TONG_HOP!A55) -> 0 | D55: {=SUMIFS(DATA_TONGHOP!N:N,DATA_TONGHOP!C:C,INDEX(DSDVI!$D$2:$D$25,MATCH(TRUE,DSDVI!$D$2:$D$25<>"",0)),DATA_TONGHOP!A:A,TONG_HOP!B55)} -> 0 | E55: =IF(C55-D55=0,0,HYPERLINK("#'"&A55&"_"&B55&"'!A1",C55-D55)) -> 0 | K55: =SUMIFS(DATA_PHATSINH!T:T,DATA_PHATSINH!M:M,"080100",DATA_PHATSINH!A:A,TONG_HOP!I55) -> 0 | L55: {=SUMIFS(DATA_PHATSINH!T:T,DATA_PHATSINH!M:M,INDEX(DSDVI!$D$2:$D$25,MATCH(TRUE,DSDVI!$D$2:$D$25<>"",0)),DATA_PHATSINH!A:A,TONG_HOP!J55)} -> 0 | M55: =IF(K55-L55=0,0,HYPERLINK("#'"&A55&"_"&B55&"'!A1",K55-L55)) -> 0
A56: Created with a trial version of Syncfusion Excel library or registered the wrong key in your application. Click here to obtain the valid key.

Sheet DSDVI
P1: Quay về TONG_HOP sheet
A5: 82900 | B5: HCMC - Công ty Điện lực Vũng Tàu | C5: HCMC - Công ty Điện lực Vũng Tàu | D5: 82900
A6: Created with a trial version of Syncfusion Excel library or registered the wrong key in your application. Click here to obtain the valid key.

Sheet DATA_TONGHOP
A1: SHTK | B1: SHTK GỐC | C1: MÃ ĐVI | D1: MÃ ĐVI NB | E1: SỐ DƯ NỢ ĐK | F1: SỐ DƯ CÓ ĐK | G1: SỐ PS NỢ | H1: SỐ PS CÓ | I1: SỐ DƯ NỢ CK | J1: SỐ DƯ CÓ CK | K1: ID | L1: ROW ORDER | M1: MA | N1: NET
A2: 1363111 | B2: 13631110000 | C2: 080100 | D2: 082900 | E2: 427522775017 | F2: 0 | G2: 103348536698 | H2: 1465071028853 | I2: 0 | J2: 934199717138 | K2: DATA_TONGHOP1 | L2: 0 | M2: =A2&C2 -> 1363111080100 | N2: =IF(C2="080100",I2-J2,J2-I2) -> -934199717138
A3: 1363112 | B3: 13631120000 | C3: 080100 | D3: 082900 | E3: 0 | F3: 3907635300 | G3: 51797384 | H3: 692814920 | I3: 0 | J3: 4548652836 | K3: DATA_TONGHOP2 | L3: 1 | M3: =A3&C3 -> 1363112080100 | N3: =IF(C3="080100",I3-J3,J3-I3) -> -4548652836
A4: 136314 | B4: 13631400000 | C4: 080100 | D4: 082900 | E4: 7987850607 | F4: 0 | G4: 0 | H4: 0 | I4: 7987850607 | J4: 0 | K4: DATA_TONGHOP3 | L4: 2 | M4: =A4&C4 -> 136314080100 | N4: =IF(C4="080100",I4-J4,J4-I4) -> 7987850607
A5: 136321 | B5: 13632100000 | C5: 080100 | D5: 082900 | E5: 0 | F5: 0 | G5: 0 | H5: 0 | I5: 0 | J5: 0 | K5: DATA_TONGHOP4 | L5: 3 | M5: =A5&C5 -> 136321080100 | N5: =IF(C5="080100",I5-J5,J5-I5) -> 0
A6: 136331 | B6: 13633100000 | C6: 080100 | D6: 082900 | E6: 0 | F6: 407915705062 | G6: 14964537632 | H6: 0 | I6: 0 | J6: 392951167430 | K6: DATA_TONGHOP5 | L6: 4 | M6: =A6&C6 -> 136331080100 | N6: =IF(C6="080100",I6-J6,J6-I6) -> -392951167430
A7: 136341 | B7: 13634100000 | C7: 080100 | D7: 082900 | E7: 0 | F7: 583672582158 | G7: 0 | H7: 0 | I7: 0 | J7: 583672582158 | K7: DATA_TONGHOP6 | L7: 5 | M7: =A7&C7 -> 136341080100 | N7: =IF(C7="080100",I7-J7,J7-I7) -> -583672582158
A8: 136351 | B8: 13635100000 | C8: 080100 | D8: 082900 | E8: 0 | F8: 19256042629 | G8: 1652341116 | H8: 0 | I8: 0 | J8: 17603701513 | K8: DATA_TONGHOP7 | L8: 6 | M8: =A8&C8 -> 136351080100 | N8: =IF(C8="080100",I8-J8,J8-I8) -> -17603701513
A9: 136351 | B9: 13635100000 | C9: 082900 | D9: 080100 | E9: 0 | F9: 0 | G9: 1074355839 | H9: 1074355839 | I9: 0 | J9: 0 | K9: DATA_TONGHOP8 | L9: 7 | M9: =A9&C9 -> 136351082900 | N9: =IF(C9="080100",I9-J9,J9-I9) -> 0
A10: 136352 | B10: 13635200000 | C10: 080100 | D10: 082900 | E10: 0 | F10: 0 | G10: 0 | H10: 0 | I10: 0 | J10: 0 | K10: DATA_TONGHOP9 | L10: 8 | M10: =A10&C10 -> 136352080100 | N10: =IF(C10="080100",I10-J10,J10-I10) -> 0
A11: 136352 | B11: 13635200000 | C11: 082900 | D11: 080100 | E11: 0 | F11: 0 | G11: 14287394776 | H11: 14287394776 | I11: 0 | J11: 0 | K11: DATA_TONGHOP10 | L11: 9 | M11: =A11&C11 -> 136352082900 | N11: =IF(C11="080100",I11-J11,J11-I11) -> 0
A12: 136358 | B12: 13635800000 | C12: 080100 | D12: 082900 | E12: 358880212978 | F12: 0 | G12: 54705959588 | H12: 104978986773 | I12: 308607185793 | J12: 0 | K12: DATA_TONGHOP11 | L12: 10 | M12: =A12&C12 -> 136358080100 | N12: =IF(C12="080100",I12-J12,J12-I12) -> 308607185793
A13: 136358 | B13: 13635800000 | C13: 082900 | D13: 080100 | E13: 0 | F13: 0 | G13: 1352970353650 | H13: 1352970353650 | I13: 0 | J13: 0 | K13: DATA_TONGHOP12 | L13: 11 | M13: =A13&C13 -> 136358082900 | N13: =IF(C13="080100",I13-J13,J13-I13) -> 0
... A46: 33693 | B46: 33693000000 | C46: 082900 | D46: 080100 | E46: 7044640797 | F46: 0 | G46: 0 | H46: 0 | I46: 7044640797 | J46: 0 | K46: DATA_TONGHOP45 | L46: 44 | M46: =A46&C46 -> 33693082900 | N46: =IF(C46="080100",I46-J46,J46-I46) -> -7044640797
A47: 13681 | B47: 13681000000 | C47: 082900 | D47: 080100 | E47: 0 | F47: 717044052 | G47: 0 | H47: 0 | I47: 0 | J47: 717044052 | M47: =A47&C47 -> 13681082900 | N47: =IF(C47="080100",I47-J47,J47-I47) -> 717044052
A48: 13681 | B48: 13681000000 | C48: 082900 | D48: 082900 | E48: 15955465293 | F48: 0 | G48: 452790220 | H48: 590829917 | I48: 15817425596 | J48: 0 | M48: =A48&C48 -> 13681082900 | N48: =IF(C48="080100",I48-J48,J48-I48) -> -15817425596
A49: 33681 | B49: 33681000000 | C49: 082900 | D49: 080100 | E49: 0 | F49: 0 | G49: 0 | H49: 0 | I49: 0 | J49: 0 | M49: =A49&C49 -> 33681082900 | N49: =IF(C49="080100",I49-J49,J49-I49) -> 0
A50: 33681 | B50: 33681000000 | C50: 082900 | D50: 082900 | E50: 0 | F50: 15238421241 | G50: 590829917 | H50: 452790220 | I50: 0 | J50: 15100381544 | M50: =A50&C50 -> 33681082900 | N50: =IF(C50="080100",I50-J50,J50-I50) -> 15100381544
M51: =A51&C51 | N51: =IF(C51="080100",I51-J51,J51-I51) -> 0
M52: =A52&C52 | N52: =IF(C52="080100",I52-J52,J52-I52) -> 0
M53: =A53&C53 | N53: =IF(C53="080100",I53-J53,J53-I53) -> 0
M54: =A54&C54 | N54: =IF(C54="080100",I54-J54,J54-I54) -> 0
M55: =A55&C55 | N55: =IF(C55="080100",I55-J55,J55-I55) -> 0
M56: =A56&C56 | N56: =IF(C56="080100",I56-J56,J56-I56) -> 0
M57: =A57&C57 | N57: =IF(C57="080100",I57-J57,J57-I57) -> 0
M58: =A58&C58 | N58: =IF(C58="080100",I58-J58,J58-I58) -> 0
M59: =A59&C59 | N59: =IF(C59="080100",I59-J59,J59-I59) -> 0
M60: =A60&C60 | N60: =IF(C60="080100",I60-J60,J60-I60) -> 0
M61: =A61&C61 | N61: =IF(C61="080100",I61-J61,J61-I61) -> 0
M62: =A62&C62 | N62: =IF(C62="080100",I62-J62,J62-I62) -> 0
... M1298: =A1298&C1298 | N1298: =IF(C1298="080100",I1298-J1298,J1298-I1298) -> 0
A1299: Created with a trial version of Syncfusion Excel library or registered the wrong key in your application. Click here to obtain the valid key.

Sheet DATA_PHATSINH
A1: SHTK | B1: SHTK GỐC | C1: NGUỒN | D1: TK CHA | E1: NHÓM TK | F1: NGÀY CT | G1: SỐ CT PHÂN HỆ PHỤ | H1: SỐ CT PHÂN HỆ GL | I1: DIỄN GIẢI | J1: SỐ PS NỢ | K1: SỐ PS CÓ | L1: NGƯỜI LẬP CT | M1: MÃ ĐVI | N1: MÃ ĐVI NB | O1: THANG | P1: NAM | Q1: ID | R1: ROW ORDER | S1: MA | T1: NET
A2: 336358 | B2: 33635800000 | C2: Cost Management-Inventory | D2: 336 | E2: 2 | F2: 2026-05-20T00:00:00+07:00 | G2: 30734260 | H2: 1574 | I2: Xuất TI Trung thế qua Đội TH2- Cty Thí Nghiệm Điện lực Thí Nghiệm | J2: 45000000 | K2: 0 | L2: THANH5DT.HCM.VTA | M2: 082900 | N2: 080100 | O2: 5 | P2: 2026 | Q2: DATA_PHATSINH1 | R2: 0 | S2: =A2&M2 -> 336358082900 | T2: =IF(M2="080100",J2-K2,K2-J2) -> -45000000
A3: 336358 | B3: 33635800000 | C3: Cost Management-Inventory | D3: 336 | E3: 2 | F3: 2026-05-20T00:00:00+07:00 | G3: 30734261 | H3: 1574 | I3: Xuất TI Trung thế qua Đội TH2- Cty Thí Nghiệm Điện lực Thí Nghiệm | J3: 45000000 | K3: 0 | L3: THANH5DT.HCM.VTA | M3: 082900 | N3: 080100 | O3: 5 | P3: 2026 | Q3: DATA_PHATSINH2 | R3: 1 | S3: =A3&M3 -> 336358082900 | T3: =IF(M3="080100",J3-K3,K3-J3) -> -45000000
A4: 336358 | B4: 33635800000 | C4: Cost Management-Inventory | D4: 336 | E4: 2 | F4: 2026-05-20T00:00:00+07:00 | G4: 30734259 | H4: 1574 | I4: Xuất TI Trung thế qua Đội TH2- Cty Thí Nghiệm Điện lực Thí Nghiệm | J4: 45000000 | K4: 0 | L4: THANH5DT.HCM.VTA | M4: 082900 | N4: 080100 | O4: 5 | P4: 2026 | Q4: DATA_PHATSINH3 | R4: 2 | S4: =A4&M4 -> 336358082900 | T4: =IF(M4="080100",J4-K4,K4-J4) -> -45000000
A5: 336358 | B5: 33635800000 | C5: Cost Management-Inventory | D5: 336 | E5: 2 | F5: 2026-05-20T00:00:00+07:00 | G5: 30734244 | H5: 1574 | I5: Xuất TI Trung thế qua Đội TH2- Cty Thí Nghiệm Điện lực Thí Nghiệm | J5: 49200000 | K5: 0 | L5: THANH5DT.HCM.VTA | M5: 082900 | N5: 080100 | O5: 5 | P5: 2026 | Q5: DATA_PHATSINH4 | R5: 3 | S5: =A5&M5 -> 336358082900 | T5: =IF(M5="080100",J5-K5,K5-J5) -> -49200000
A6: 336358 | B6: 33635800000 | C6: Cost Management-Inventory | D6: 336 | E6: 2 | F6: 2026-05-20T00:00:00+07:00 | G6: 30734245 | H6: 1574 | I6: Xuất TI Trung thế qua Đội TH2- Cty Thí Nghiệm Điện lực Thí Nghiệm | J6: 52800000 | K6: 0 | L6: THANH5DT.HCM.VTA | M6: 082900 | N6: 080100 | O6: 5 | P6: 2026 | Q6: DATA_PHATSINH5 | R6: 4 | S6: =A6&M6 -> 336358082900 | T6: =IF(M6="080100",J6-K6,K6-J6) -> -52800000
A7: 336358 | B7: 33635800000 | C7: Cost Management-Inventory | D7: 336 | E7: 2 | F7: 2026-05-20T00:00:00+07:00 | G7: 30734258 | H7: 1574 | I7: Xuất TI Trung thế qua Đội TH2- Cty Thí Nghiệm Điện lực Thí Nghiệm | J7: 54000000 | K7: 0 | L7: THANH5DT.HCM.VTA | M7: 082900 | N7: 080100 | O7: 5 | P7: 2026 | Q7: DATA_PHATSINH6 | R7: 5 | S7: =A7&M7 -> 336358082900 | T7: =IF(M7="080100",J7-K7,K7-J7) -> -54000000
A8: 336358 | B8: 33635800000 | C8: Cost Management-Inventory | D8: 336 | E8: 2 | F8: 2026-05-11T00:00:00+07:00 | G8: 30682048 | H8: 1573 | I8: Xuất công tơ lên Cty Thí Nghiệm kiểm định ( VB : 2005/PCVT-KHVT ) | J8: 61055399 | K8: 0 | L8: THANH5DT.HCM.VTA | M8: 082900 | N8: 080100 | O8: 5 | P8: 2026 | Q8: DATA_PHATSINH7 | R8: 6 | S8: =A8&M8 -> 336358082900 | T8: =IF(M8="080100",J8-K8,K8-J8) -> -61055399
A9: 336358 | B9: 33635800000 | C9: Cost Management-Inventory | D9: 336 | E9: 2 | F9: 2026-05-29T00:00:00+07:00 | G9: 30793502 | H9: 1585 | I9: Xuất công tơ 1 pha 3 giá lên kiểm định | J9: 70059644 | K9: 0 | L9: THANH5DT.HCM.VTA | M9: 082900 | N9: 080100 | O9: 5 | P9: 2026 | Q9: DATA_PHATSINH8 | R9: 7 | S9: =A9&M9 -> 336358082900 | T9: =IF(M9="080100",J9-K9,K9-J9) -> -70059644
A10: 336358 | B10: 33635800000 | C10: Cost Management-Inventory | D10: 336 | E10: 2 | F10: 2026-05-20T00:00:00+07:00 | G10: 30734246 | H10: 1574 | I10: Xuất TI Trung thế qua Đội TH2- Cty Thí Nghiệm Điện lực Thí Nghiệm | J10: 74711443 | K10: 0 | L10: THANH5DT.HCM.VTA | M10: 082900 | N10: 080100 | O10: 5 | P10: 2026 | Q10: DATA_PHATSINH9 | R10: 8 | S10: =A10&M10 -> 336358082900 | T10: =IF(M10="080100",J10-K10,K10-J10) -> -74711443
A11: 336358 | B11: 33635800000 | C11: Cost Management-Inventory | D11: 336 | E11: 2 | F11: 2026-05-20T00:00:00+07:00 | G11: 30734242 | H11: 1574 | I11: Xuất TI Trung thế qua Đội TH2- Cty Thí Nghiệm Điện lực Thí Nghiệm | J11: 79200000 | K11: 0 | L11: THANH5DT.HCM.VTA | M11: 082900 | N11: 080100 | O11: 5 | P11: 2026 | Q11: DATA_PHATSINH10 | R11: 9 | S11: =A11&M11 -> 336358082900 | T11: =IF(M11="080100",J11-K11,K11-J11) -> -79200000
A12: 336358 | B12: 33635800000 | C12: Cost Management-Inventory | D12: 336 | E12: 2 | F12: 2026-05-20T00:00:00+07:00 | G12: 30734262 | H12: 1574 | I12: Xuất TI Trung thế qua Đội TH2- Cty Thí Nghiệm Điện lực Thí Nghiệm | J12: 30000000 | K12: 0 | L12: THANH5DT.HCM.VTA | M12: 082900 | N12: 080100 | O12: 5 | P12: 2026 | Q12: DATA_PHATSINH11 | R12: 10 | S12: =A12&M12 -> 336358082900 | T12: =IF(M12="080100",J12-K12,K12-J12) -> -30000000
A13: 336358 | B13: 33635800000 | C13: Cost Management-Inventory | D13: 336 | E13: 2 | F13: 2026-05-25T00:00:00+07:00 | G13: 30757320 | H13: 1580 | I13: Xuất công tơ lên Cty Thí Nghiệm cài đặt lại tỉ số | J13: 89940000 | K13: 0 | L13: THANH5DT.HCM.VTA | M13: 082900 | N13: 080100 | O13: 5 | P13: 2026 | Q13: DATA_PHATSINH12 | R13: 11 | S13: =A13&M13 -> 336358082900 | T13: =IF(M13="080100",J13-K13,K13-J13) -> -89940000
... A118: 3363883 | B118: 33638830000 | C118: Cost Management-Inventory | D118: 336 | E118: 2 | F118: 2026-05-27T00:00:00+07:00 | G118: 30777785 | H118: 1587 | I118: 25041: Nhập Vtư điều động TB 2431/TB-EVNHCMC ngày 15.5.26, theo HD số 761/26.05.26 của TCty ĐLTPHCM (03.UVL.57.0047/26.05.26) | J118: 0 | K118: 4700000000 | L118: THANH5DT.HCM.VTA | M118: 082900 | N118: 080100 | O118: 5 | P118: 2026 | Q118: DATA_PHATSINH117 | R118: 116 | S118: =A118&M118 -> 3363883082900 | T118: =IF(M118="080100",J118-K118,K118-J118) -> 4700000000
A119: 1363111 | B119: 13631110000 | C119: GL-MANUAL | D119: 136 | E119: 1 | F119: 2026-05-31T00:00:00+07:00 | H119: 5092 | I119: KC PTNB TIEN DIEN THANG 5-2026 - PCVT | J119: 0 | K119: 1006728865803 | L119: ANHTTL.HCM.NG | M119: 080100 | N119: 082900 | O119: 5 | P119: 2026 | Q119: DATA_PHATSINH118 | R119: 117 | S119: =A119&M119 -> 1363111080100 | T119: =IF(M119="080100",J119-K119,K119-J119) -> -1006728865803
A120: 1363111 | B120: 13631110000 | C120: GL-MANUAL | D120: 136 | E120: 1 | F120: 2026-05-31T00:00:00+07:00 | H120: 5047 | I120: THOÁI HOÀN TIỀN ĐIỆN THÁNG 05/2026 Vũng Tàu | J120: 40655098 | K120: 0 | L120: TRANGLTT.HCM.NG | M120: 080100 | N120: 082900 | O120: 5 | P120: 2026 | Q120: DATA_PHATSINH119 | R120: 118 | S120: =A120&M120 -> 1363111080100 | T120: =IF(M120="080100",J120-K120,K120-J120) -> 40655098
A121: 136358 | B121: 13635800000 | C121: GL-MANUAL | D121: 136 | E121: 1 | F121: 2026-05-31T00:00:00+07:00 | H121: 5029 | I121: VTDD T5/2026 VT (SXKD) | J121: 0 | K121: 1619307789 | L121: NAM7NH.HCM.NG | M121: 080100 | N121: 082900 | O121: 5 | P121: 2026 | Q121: DATA_PHATSINH120 | R121: 119 | S121: =A121&M121 -> 136358080100 | T121: =IF(M121="080100",J121-K121,K121-J121) -> -1619307789
A122: 1363883 | B122: 13638830000 | C122: GL-MANUAL | D122: 136 | E122: 1 | F122: 2026-05-31T00:00:00+07:00 | H122: 5035 | I122: VTDD T05/2026 DVĐL -> VT | J122: 17718778000 | K122: 0 | L122: NAM7NH.HCM.NG | M122: 080100 | N122: 082900 | O122: 5 | P122: 2026 | Q122: DATA_PHATSINH121 | R122: 120 | S122: =A122&M122 -> 1363883080100 | T122: =IF(M122="080100",J122-K122,K122-J122) -> 17718778000
A123: 3363888 | B123: 33638880000 | C123: GL-MANUAL | D123: 336 | E123: 2 | F123: 2026-05-31T00:00:00+07:00 | H123: 5047 | I123: THOÁI HOÀN TIỀN ĐIỆN T.05/2026 | J123: 0 | K123: 40655098 | L123: TRANGLTT.HCM.NG | M123: 080100 | N123: 082900 | O123: 5 | P123: 2026 | Q123: DATA_PHATSINH122 | R123: 121 | S123: =A123&M123 -> 3363888080100 | T123: =IF(M123="080100",J123-K123,K123-J123) -> -40655098
A124: 136358 | B124: 13635800000 | C124: GL-MANUAL | D124: 136 | E124: 1 | F124: 2026-05-31T00:00:00+07:00 | H124: 5032 | I124: VTDD T5/2026 TNĐL -> VT | J124: 1579969634 | K124: 0 | L124: NAM7NH.HCM.NG | M124: 080100 | N124: 082900 | O124: 5 | P124: 2026 | Q124: DATA_PHATSINH123 | R124: 122 | S124: =A124&M124 -> 136358080100 | T124: =IF(M124="080100",J124-K124,K124-J124) -> 1579969634
A125: 136358 | B125: 13635800000 | C125: GL-MANUAL | D125: 136 | E125: 1 | F125: 2026-05-31T00:00:00+07:00 | H125: 5035 | I125: VTDD T05/2026 DVĐL -> VT | J125: 1397373643 | K125: 0 | L125: NAM7NH.HCM.NG | M125: 080100 | N125: 082900 | O125: 5 | P125: 2026 | Q125: DATA_PHATSINH124 | R125: 123 | S125: =A125&M125 -> 136358080100 | T125: =IF(M125="080100",J125-K125,K125-J125) -> 1397373643
A126: 33688 | B126: 33688000000 | C126: GL-MANUAL | D126: 336 | E126: 2 | F126: 2026-05-31T00:00:00+07:00 | H126: 5092 | I126: KC PTNB TIEN DIEN THANG 5-2026 - PCVT | J126: 1006728865803 | K126: 0 | L126: ANHTTL.HCM.NG | M126: 080100 | N126: 082900 | O126: 5 | P126: 2026 | Q126: DATA_PHATSINH125 | R126: 124 | S126: =A126&M126 -> 33688080100 | T126: =IF(M126="080100",J126-K126,K126-J126) -> 1006728865803
A127: 33688 | B127: 33688000000 | C127: GL-MANUAL | D127: 336 | E127: 2 | F127: 2026-05-31T00:00:00+07:00 | H127: 5092 | I127: KC PTNB TIEN DIEN THANG 5-2026 - PCVT (VC) | J127: 301236589 | K127: 0 | L127: ANHTTL.HCM.NG | M127: 080100 | N127: 082900 | O127: 5 | P127: 2026 | Q127: DATA_PHATSINH126 | R127: 125 | S127: =A127&M127 -> 33688080100 | T127: =IF(M127="080100",J127-K127,K127-J127) -> 301236589
A128: 1363112 | B128: 13631120000 | C128: GL-MANUAL | D128: 136 | E128: 1 | F128: 2026-05-31T00:00:00+07:00 | H128: 5092 | I128: KC PTNB TIEN DIEN THANG 5-2026 - PCVT (VC) | J128: 0 | K128: 301236589 | L128: ANHTTL.HCM.NG | M128: 080100 | N128: 082900 | O128: 5 | P128: 2026 | Q128: DATA_PHATSINH127 | R128: 126 | S128: =A128&M128 -> 1363112080100 | T128: =IF(M128="080100",J128-K128,K128-J128) -> -301236589
A129: 336358 | B129: 33635800000 | C129: GL-MANUAL | D129: 336 | E129: 2 | F129: 2026-05-31T00:00:00+07:00 | H129: 1631 | I129: Kết chuyển công nợ nội bộ tháng 05/2026 | J129: 47447508936 | K129: 0 | L129: DUYENTT.HCM.VTA | M129: 082900 | N129: 080100 | O129: 5 | P129: 2026 | Q129: DATA_PHATSINH128 | R129: 127 | S129: =A129&M129 -> 336358082900 | T129: =IF(M129="080100",J129-K129,K129-J129) -> -47447508936
A130: 3363883 | B130: 33638830000 | C130: GL-MANUAL | D130: 336 | E130: 2 | F130: 2026-05-31T00:00:00+07:00 | H130: 1361 | I130: Thuế GTGT VTĐĐ- hđơn 666-11.05.26-TỔNG CÔNG TY ĐIỆN LỰC THÀNH PHỐ HỒ CHÍ MINH | J130: 0 | K130: 25728000 | L130: THANH5DT.HCM.VTA | M130: 082900 | N130: 080100 | O130: 5 | P130: 2026 | Q130: DATA_PHATSINH129 | R130: 128 | S130: =A130&M130 -> 3363883082900 | T130: =IF(M130="080100",J130-K130,K130-J130) -> 25728000
... A326: 136358 | B326: 13635800000 | C326: MassAllocation-Allocation | D326: 136 | E326: 1 | F326: 2026-05-31T00:00:00+07:00 | H326: 1613 | I326: K/c 64298 (Điện) > 136358 | J326: 824548335 | K326: 0 | L326: DUYENTT.HCM.VTA | M326: 082900 | N326: 080100 | O326: 5 | P326: 2026 | Q326: DATA_PHATSINH325 | R326: 324 | S326: =A326&M326 -> 136358082900 | T326: =IF(M326="080100",J326-K326,K326-J326) -> -824548335
A327: 3363112 | B327: 33631120000 | C327: Receivables-Credit Memos | D327: 336 | E327: 2 | F327: 2026-05-29T00:00:00+07:00 | G327: 1635 | H327: 1431 | I327: Giải trừ tiền vô công thu hộ CTĐLVT ngày 29/05/2026 | J327: 250601 | K327: 0 | L327: CHAULTN.HCM.VTA | M327: 082900 | N327: 080100 | O327: 5 | P327: 2026 | Q327: DATA_PHATSINH326 | R327: 325 | S327: =A327&M327 -> 3363112082900 | T327: =IF(M327="080100",J327-K327,K327-J327) -> -250601
A328: 3363112 | B328: 33631120000 | C328: Receivables-Credit Memos | D328: 336 | E328: 2 | F328: 2026-05-20T00:00:00+07:00 | G328: 1581 | H328: 1424 | I328: Giải trừ tiền vô công thu hộ CTĐLVT ngày 20/05/2026 | J328: 556655 | K328: 0 | L328: CHAULTN.HCM.VTA | M328: 082900 | N328: 080100 | O328: 5 | P328: 2026 | Q328: DATA_PHATSINH327 | R328: 326 | S328: =A328&M328 -> 3363112082900 | T328: =IF(M328="080100",J328-K328,K328-J328) -> -556655
A329: 3363112 | B329: 33631120000 | C329: Receivables-Credit Memos | D329: 336 | E329: 2 | F329: 2026-05-21T00:00:00+07:00 | G329: 1611 | H329: 1436 | I329: Giải trừ tiền vô công thu hộ CTĐLVT ngày 21/05/2026 | J329: 928022 | K329: 0 | L329: CHAULTN.HCM.VTA | M329: 082900 | N329: 080100 | O329: 5 | P329: 2026 | Q329: DATA_PHATSINH328 | R329: 327 | S329: =A329&M329 -> 3363112082900 | T329: =IF(M329="080100",J329-K329,K329-J329) -> -928022
A330: 3363112 | B330: 33631120000 | C330: Receivables-Credit Memos | D330: 336 | E330: 2 | F330: 2026-05-11T00:00:00+07:00 | G330: 1591 | H330: 1435 | I330: Giải trừ tiền vô công thu hộ CTĐLVT ngày 11/05/2026 | J330: 1195232 | K330: 0 | L330: CHAULTN.HCM.VTA | M330: 082900 | N330: 080100 | O330: 5 | P330: 2026 | Q330: DATA_PHATSINH329 | R330: 328 | S330: =A330&M330 -> 3363112082900 | T330: =IF(M330="080100",J330-K330,K330-J330) -> -1195232
A331: 3363112 | B331: 33631120000 | C331: Receivables-Credit Memos | D331: 336 | E331: 2 | F331: 2026-05-19T00:00:00+07:00 | G331: 1578 | H331: 1418 | I331: Giải trừ tiền vô công thu hộ CTĐLVT ngày 19/05/2026 | J331: 2635359 | K331: 0 | L331: CHAULTN.HCM.VTA | M331: 082900 | N331: 080100 | O331: 5 | P331: 2026 | Q331: DATA_PHATSINH330 | R331: 329 | S331: =A331&M331 -> 3363112082900 | T331: =IF(M331="080100",J331-K331,K331-J331) -> -2635359
A332: 3363112 | B332: 33631120000 | C332: Receivables-Credit Memos | D332: 336 | E332: 2 | F332: 2026-05-13T00:00:00+07:00 | G332: 1594 | H332: 1421 | I332: Giải trừ tiền vô công thu hộ CTĐLVT ngày 13/05/2026 | J332: 3954874 | K332: 0 | L332: CHAULTN.HCM.VTA | M332: 082900 | N332: 080100 | O332: 5 | P332: 2026 | Q332: DATA_PHATSINH331 | R332: 330 | S332: =A332&M332 -> 3363112082900 | T332: =IF(M332="080100",J332-K332,K332-J332) -> -3954874
A333: 3363111 | B333: 33631110000 | C333: Receivables-Credit Memos | D333: 336 | E333: 2 | F333: 2026-05-01T00:00:00+07:00 | G333: 1555 | H333: 1423 | I333: Giải trừ tiền điện thu hộ CTĐLVT ngày 01/05/2026 | J333: 18128980 | K333: 0 | L333: CHAULTN.HCM.VTA | M333: 082900 | N333: 080100 | O333: 5 | P333: 2026 | Q333: DATA_PHATSINH332 | R333: 331 | S333: =A333&M333 -> 3363111082900 | T333: =IF(M333="080100",J333-K333,K333-J333) -> -18128980
A334: 3363111 | B334: 33631110000 | C334: Receivables-Credit Memos | D334: 336 | E334: 2 | F334: 2026-05-02T00:00:00+07:00 | G334: 1556 | H334: 1426 | I334: Giải trừ tiền điện thu hộ CTĐLVT ngày 02/05/2026 | J334: 26816550 | K334: 0 | L334: CHAULTN.HCM.VTA | M334: 082900 | N334: 080100 | O334: 5 | P334: 2026 | Q334: DATA_PHATSINH333 | R334: 332 | S334: =A334&M334 -> 3363111082900 | T334: =IF(M334="080100",J334-K334,K334-J334) -> -26816550
A335: 3363111 | B335: 33631110000 | C335: Receivables-Credit Memos | D335: 336 | E335: 2 | F335: 2026-05-31T00:00:00+07:00 | G335: 1637 | H335: 1410 | I335: Giải trừ tiền điện thu hộ CTĐLVT ngày 31/05/2026 | J335: 124625041 | K335: 0 | L335: CHAULTN.HCM.VTA | M335: 082900 | N335: 080100 | O335: 5 | P335: 2026 | Q335: DATA_PHATSINH334 | R335: 333 | S335: =A335&M335 -> 3363111082900 | T335: =IF(M335="080100",J335-K335,K335-J335) -> -124625041
A336: 3363111 | B336: 33631110000 | C336: Receivables-Credit Memos | D336: 336 | E336: 2 | F336: 2026-05-29T00:00:00+07:00 | G336: 1634 | H336: 1431 | I336: Giải trừ tiền điện thu hộ CTĐLVT ngày 29/05/2026 | J336: 213369327 | K336: 0 | L336: CHAULTN.HCM.VTA | M336: 082900 | N336: 080100 | O336: 5 | P336: 2026 | Q336: DATA_PHATSINH335 | R336: 334 | S336: =A336&M336 -> 3363111082900 | T336: =IF(M336="080100",J336-K336,K336-J336) -> -213369327
A337: 3363111 | B337: 33631110000 | C337: Receivables-Credit Memos | D337: 336 | E337: 2 | F337: 2026-05-30T00:00:00+07:00 | G337: 1636 | H337: 1432 | I337: Giải trừ tiền điện thu hộ CTĐLVT ngày 30/05/2026 | J337: 240583866 | K337: 0 | L337: CHAULTN.HCM.VTA | M337: 082900 | N337: 080100 | O337: 5 | P337: 2026 | Q337: DATA_PHATSINH336 | R337: 335 | S337: =A337&M337 -> 3363111082900 | T337: =IF(M337="080100",J337-K337,K337-J337) -> -240583866
A338: 3363111 | B338: 33631110000 | C338: Receivables-Credit Memos | D338: 336 | E338: 2 | F338: 2026-05-28T00:00:00+07:00 | G338: 1645 | H338: 1434 | I338: Giải trừ tiền điện thu hộ CTĐLVT ngày 28/05/2026 | J338: 261690745 | K338: 0 | L338: CHAULTN.HCM.VTA | M338: 082900 | N338: 080100 | O338: 5 | P338: 2026 | Q338: DATA_PHATSINH337 | R338: 336 | S338: =A338&M338 -> 3363111082900 | T338: =IF(M338="080100",J338-K338,K338-J338) -> -261690745
... A373: 3363112 | B373: 33631120000 | C373: Receivables-Credit Memos | D373: 336 | E373: 2 | F373: 2026-05-04T00:00:00+07:00 | G373: 1568 | H373: 1419 | I373: Giải trừ tiền vô công thu hộ CTĐLVT ngày 04/05/2026 | J373: 121340050 | K373: 0 | L373: CHAULTN.HCM.VTA | M373: 082900 | N373: 080100 | O373: 5 | P373: 2026 | Q373: DATA_PHATSINH372 | R373: 371 | S373: =A373&M373 -> 3363112082900 | T373: =IF(M373="080100",J373-K373,K373-J373) -> -121340050
...

Sheet 1363111_3363111
A1: Madonvi | B1: NhomTK | C1: SoHieuTaiKhoan | D1: NGUON | E1: DienGiai | F1: SoCTPhanHePhu | G1: SoCTPhanHeGL | H1: SoPSNo | I1: SoPSCo | J1: NguoiLapCT | K1: Thang | L1: NET | M1: Trung | N1: VLOOKUP_NET | O1: id | P1: =HYPERLINK("#TONG_HOP!G1","TRO VE") -> TRO VE
A2: 80100 | B2: 1 | C2: 1363111 | D2: GL-MANUAL | E2: KC PTNB TIEN DIEN THANG 5-2026 - PCVT | G2: 5092 | H2: 0 | I2: 1006728865803 | J2: ANHTTL.HCM.NG | K2: 5 | L2: -1006728865803 | M2: FALSE | N2: -1006728865803_5 | O2: CHITIET1 | P2: 0
A3: 82900 | B3: 2 | C3: 3363111 | D3: GL-MANUAL | E3: KC Thuế GTGT VTĐĐ- hđơn 666-11.05.26-TỔNG CÔNG TY ĐIỆN LỰC THÀNH PHỐ HỒ CHÍ MINH | G3: 1361 | H3: 0 | I3: 25728000 | J3: THANH5DT.HCM.VTA | K3: 5 | L3: 25728000 | M3: FALSE | N3: 25728000_5 | O3: CHITIET2 | P3: 1
A4: 82900 | B4: 2 | C4: 3363111 | D4: GL-MANUAL | E4: KC Thuế GTGT VTĐĐ- hđơn 681-13.05.26-TỔNG CÔNG TY ĐIỆN LỰC THÀNH PHỐ HỒ CHÍ MINH | G4: 1361 | H4: 0 | I4: 102912000 | J4: THANH5DT.HCM.VTA | K4: 5 | L4: 102912000 | M4: FALSE | N4: 102912000_5 | O4: CHITIET3 | P4: 2
A5: 82900 | B5: 2 | C5: 3363111 | D5: GL-MANUAL | E5: KC Thuế GTGT VTĐĐ- hđơn 760-26.05.26-TỔNG CÔNG TY ĐIỆN LỰC THÀNH PHỐ HỒ CHÍ MINH | G5: 1361 | H5: 0 | I5: 376000000 | J5: THANH5DT.HCM.VTA | K5: 5 | L5: 376000000 | M5: FALSE | N5: 376000000_5 | O5: CHITIET4 | P5: 3
A6: 82900 | B6: 2 | C6: 3363111 | D6: GL-MANUAL | E6: KC Thuế GTGT VTĐĐ- hđơn 761-26.05.26-TỔNG CÔNG TY ĐIỆN LỰC THÀNH PHỐ HỒ CHÍ MINH | G6: 1361 | H6: 0 | I6: 376000000 | J6: THANH5DT.HCM.VTA | K6: 5 | L6: 376000000 | M6: FALSE | N6: 376000000_5 | O6: CHITIET5 | P6: 4
A7: 82900 | B7: 2 | C7: 3363111 | D7: GL-MANUAL | E7: KC Thuế GTGT VTĐĐ- hđơn 752-25.05.26-TỔNG CÔNG TY ĐIỆN LỰC THÀNH PHỐ HỒ CHÍ MINH | G7: 1361 | H7: 0 | I7: 144771840 | J7: THANH5DT.HCM.VTA | K7: 5 | L7: 144771840 | M7: FALSE | N7: 144771840_5 | O7: CHITIET6 | P7: 5
A8: 82900 | B8: 2 | C8: 3363111 | D8: GL-MANUAL | E8: KC Thuế GTGT VTĐĐ- hđơn 762-26.05.26-TỔNG CÔNG TY ĐIỆN LỰC THÀNH PHỐ HỒ CHÍ MINH | G8: 1361 | H8: 0 | I8: 289543680 | J8: THANH5DT.HCM.VTA | K8: 5 | L8: 289543680 | M8: FALSE | N8: 289543680_5 | O8: CHITIET7 | P8: 6
A9: 82900 | B9: 2 | C9: 3363111 | D9: GL-MANUAL | E9: KC Thuế GTGT VTĐĐ- hđơn 780-27.05.26-TỔNG CÔNG TY ĐIỆN LỰC THÀNH PHỐ HỒ CHÍ MINH | G9: 1361 | H9: 0 | I9: 102546720 | J9: THANH5DT.HCM.VTA | K9: 5 | L9: 102546720 | M9: FALSE | N9: 102546720_5 | O9: CHITIET8 | P9: 7
A10: 82900 | B10: 2 | C10: 3363111 | D10: GL-MANUAL | E10: KC Thuế GTGT VTĐĐ- hđơn 709-19.05.26-TỔNG CÔNG TY ĐIỆN LỰC THÀNH PHỐ HỒ CHÍ MINH | G10: 1361 | H10: 0 | I10: 13464000 | J10: THANH5DT.HCM.VTA | K10: 5 | L10: 13464000 | M10: FALSE | N10: 13464000_5 | O10: CHITIET9 | P10: 8
A11: 82900 | B11: 2 | C11: 3363111 | D11: GL-MANUAL | E11: KC Thuế GTGT VTĐĐ- hđơn 710-19.05.26-TỔNG CÔNG TY ĐIỆN LỰC THÀNH PHỐ HỒ CHÍ MINH | G11: 1361 | H11: 0 | I11: 18072915 | J11: THANH5DT.HCM.VTA | K11: 5 | L11: 18072915 | M11: FALSE | N11: 18072915_5 | O11: CHITIET10 | P11: 9
A12: 82900 | B12: 2 | C12: 3363111 | D12: GL-MANUAL | E12: KC Thuế GTGT VTĐĐ- hđơn 708-19.05.26-TỔNG CÔNG TY ĐIỆN LỰC THÀNH PHỐ HỒ CHÍ MINH | G12: 1361 | H12: 0 | I12: 26588976 | J12: THANH5DT.HCM.VTA | K12: 5 | L12: 26588976 | M12: FALSE | N12: 26588976_5 | O12: CHITIET11 | P12: 10
A13: 82900 | B13: 2 | C13: 3363111 | D13: GL-MANUAL | E13: KC Thuế GTGT VTĐĐ- hđơn 679-13.05.26-TỔNG CÔNG TY ĐIỆN LỰC THÀNH PHỐ HỒ CHÍ MINH | G13: 1361 | H13: 0 | I13: 53664000 | J13: THANH5DT.HCM.VTA | K13: 5 | L13: 53664000 | M13: FALSE | N13: 53664000_5 | O13: CHITIET12 | P13: 11
... A16: 82900 | B16: 2 | C16: 3363111 | D16: MassAllocation-Allocation | E16: K/c 51111 > 3363111 (k/c doanh thu điện) | G16: 1622 | H16: 0 | I16: 1420763729435 | J16: DUYENTT.HCM.VTA | K16: 5 | L16: 1420763729435 | M16: FALSE | N16: 1420763729435_5 | O16: CHITIET15 | P16: 14
A17: 82900 | B17: 2 | C17: 3363111 | D17: Receivables-Credit Memos | E17: Giải trừ tiền điện thu hộ CTĐLVT ngày 01/05/2026 | F17: 1555 | G17: 1423 | H17: 18128980 | I17: 0 | J17: CHAULTN.HCM.VTA | K17: 5 | L17: -18128980 | M17: FALSE | N17: -18128980_5 | O17: CHITIET16 | P17: 15
A18: 82900 | B18: 2 | C18: 3363111 | D18: Receivables-Credit Memos | E18: Giải trừ tiền điện thu hộ CTĐLVT ngày 02/05/2026 | F18: 1556 | G18: 1426 | H18: 26816550 | I18: 0 | J18: CHAULTN.HCM.VTA | K18: 5 | L18: -26816550 | M18: FALSE | N18: -26816550_5 | O18: CHITIET17 | P18: 16
A19: 82900 | B19: 2 | C19: 3363111 | D19: Receivables-Credit Memos | E19: Giải trừ tiền điện thu hộ CTĐLVT ngày 31/05/2026 | F19: 1637 | G19: 1410 | H19: 124625041 | I19: 0 | J19: CHAULTN.HCM.VTA | K19: 5 | L19: -124625041 | M19: FALSE | N19: -124625041_5 | O19: CHITIET18 | P19: 17
A20: 82900 | B20: 2 | C20: 3363111 | D20: Receivables-Credit Memos | E20: Giải trừ tiền điện thu hộ CTĐLVT ngày 29/05/2026 | F20: 1634 | G20: 1431 | H20: 213369327 | I20: 0 | J20: CHAULTN.HCM.VTA | K20: 5 | L20: -213369327 | M20: FALSE | N20: -213369327_5 | O20: CHITIET19 | P20: 18
A21: 82900 | B21: 2 | C21: 3363111 | D21: Receivables-Credit Memos | E21: Giải trừ tiền điện thu hộ CTĐLVT ngày 30/05/2026 | F21: 1636 | G21: 1432 | H21: 240583866 | I21: 0 | J21: CHAULTN.HCM.VTA | K21: 5 | L21: -240583866 | M21: FALSE | N21: -240583866_5 | O21: CHITIET20 | P21: 19
A22: 82900 | B22: 2 | C22: 3363111 | D22: Receivables-Credit Memos | E22: Giải trừ tiền điện thu hộ CTĐLVT ngày 28/05/2026 | F22: 1645 | G22: 1434 | H22: 261690745 | I22: 0 | J22: CHAULTN.HCM.VTA | K22: 5 | L22: -261690745 | M22: FALSE | N22: -261690745_5 | O22: CHITIET21 | P22: 20
A23: 82900 | B23: 2 | C23: 3363111 | D23: Receivables-Credit Memos | E23: Giải trừ tiền điện thu hộ CTĐLVT ngày 27/05/2026 | F23: 1644 | G23: 1433 | H23: 589602156 | I23: 0 | J23: CHAULTN.HCM.VTA | K23: 5 | L23: -589602156 | M23: FALSE | N23: -589602156_5 | O23: CHITIET22 | P23: 21
A24: 82900 | B24: 2 | C24: 3363111 | D24: Receivables-Credit Memos | E24: Giải trừ tiền điện thu hộ CTĐLVT ngày 21/05/2026 | F24: 1610 | G24: 1436 | H24: 2031335542 | I24: 0 | J24: CHAULTN.HCM.VTA | K24: 5 | L24: -2031335542 | M24: FALSE | N24: -2031335542_5 | O24: CHITIET23 | P24: 22
A25: 82900 | B25: 2 | C25: 3363111 | D25: Receivables-Credit Memos | E25: Giải trừ tiền điện thu hộ CTĐLVT ngày 23/05/2026 | F25: 1619 | G25: 1440 | H25: 2196560832 | I25: 0 | J25: CHAULTN.HCM.VTA | K25: 5 | L25: -2196560832 | M25: FALSE | N25: -2196560832_5 | O25: CHITIET24 | P25: 23
A26: 82900 | B26: 2 | C26: 3363111 | D26: Receivables-Credit Memos | E26: Giải trừ tiền điện thu hộ CTĐLVT ngày 19/05/2026 | F26: 1577 | G26: 1418 | H26: 2571762995 | I26: 0 | J26: CHAULTN.HCM.VTA | K26: 5 | L26: -2571762995 | M26: FALSE | N26: -2571762995_5 | O26: CHITIET25 | P26: 24
A27: 82900 | B27: 2 | C27: 3363111 | D27: Receivables-Credit Memos | E27: Giải trừ tiền điện thu hộ CTĐLVT ngày 26/05/2026 | F27: 1629 | G27: 1425 | H27: 2884615550 | I27: 0 | J27: CHAULTN.HCM.VTA | K27: 5 | L27: -2884615550 | M27: FALSE | N27: -2884615550_5 | O27: CHITIET26 | P27: 25
A28: 82900 | B28: 2 | C28: 3363111 | D28: Receivables-Credit Memos | E28: Giải trừ tiền điện thu hộ CTĐLVT ngày 20/05/2026 | F28: 1580 | G28: 1424 | H28: 3039901153 | I28: 0 | J28: CHAULTN.HCM.VTA | K28: 5 | L28: -3039901153 | M28: FALSE | N28: -3039901153_5 | O28: CHITIET27 | P28: 26
... A43: 82900 | B43: 2 | C43: 3363111 | D43: Receivables-Credit Memos | E43: Giải trừ tiền điện thu hộ CTĐLVT ngày 04/05/2026 | F43: 1567 | G43: 1419 | H43: 172475203824 | I43: 0 | J43: CHAULTN.HCM.VTA | K43: 5 | L43: -172475203824 | M43: FALSE | N43: -172475203824_5 | O43: CHITIET42 | P43: 41
A44: 80100 | B44: 1 | C44: 1363111 | D44: Receivables-Misc Receipts | E44: TD - ACB - VTA | F44: ACBO202605310 | G44: 5114 | H44: 0 | I44: 4466593 | J44: VIETDT.HCM.NG | K44: 5 | L44: -4466593 | M44: FALSE | N44: -4466593_5 | O44: CHITIET43 | P44: 42
A45: 80100 | B45: 1 | C45: 1363111 | D45: Receivables-Misc Receipts | E45: TD - NAB - VTA | F45: NABO202605110 | G45: 5121 | H45: 0 | I45: 4708410 | J45: VIETDT.HCM.NG | K45: 5 | L45: -4708410 | M45: FALSE | N45: -4708410_5 | O45: CHITIET44 | P45: 43
A46: 80100 | B46: 1 | C46: 1363111 | D46: Receivables-Misc Receipts | E46: TD - BIDV - VTA | F46: BIDVO202605010 | G46: 5122 | H46: 0 | I46: 4937332 | J46: VIETDT.HCM.NG | K46: 5 | L46: -4937332 | M46: FALSE | N46: -4937332_5 | O46: CHITIET45 | P46: 44
A47: 80100 | B47: 1 | C47: 1363111 | D47: Receivables-Misc Receipts | E47: TD - ICB - VTA | F47: ICBO202605290 | G47: 5100 | H47: 0 | I47: 3986735 | J47: VIETDT.HCM.NG | K47: 5 | L47: -3986735 | M47: FALSE | N47: -3986735_5 | O47: CHITIET46 | P47: 45
A48: 80100 | B48: 1 | C48: 1363111 | D48: Receivables-Misc Receipts | E48: TD - NAB - VTA | F48: NABO202605130 | G48: 5123 | H48: 0 | I48: 3993560 | J48: VIETDT.HCM.NG | K48: 5 | L48: -3993560 | M48: FALSE | N48: -3993560_5 | O48: CHITIET47 | P48: 46
A49: 80100 | B49: 1 | C49: 1363111 | D49: Receivables-Misc Receipts | E49: TD - VPB - VTA | F49: VPBO202605230 | G49: 5101 | H49: 0 | I49: 4157374 | J49: VIETDT.HCM.NG | K49: 5 | L49: -4157374 | M49: FALSE | N49: -4157374_5 | O49: CHITIET48 | P49: 47
A50: 80100 | B50: 1 | C50: 1363111 | D50: Receivables-Misc Receipts | E50: TD - VPB - VTA | F50: VPBO202605210 | G50: 5099 | H50: 0 | I50: 4242149 | J50: VIETDT.HCM.NG | K50: 5 | L50: -4242149 | M50: FALSE | N50: -4242149_5 | O50: CHITIET49 | P50: 48
A51: 80100 | B51: 1 | C51: 1363111 | D51: Receivables-Misc Receipts | E51: TD - SCB - VTA | F51: SCBO202605310 | G51: 5114 | H51: 0 | I51: 4249109 | J51: VIETDT.HCM.NG | K51: 5 | L51: -4249109 | M51: FALSE | N51: -4249109_5 | O51: CHITIET50 | P51: 49
A52: 80100 | B52: 1 | C52: 1363111 | D52: Receivables-Misc Receipts | E52: TD - ACB - VTA | F52: ACBO202605300 | G52: 5115 | H52: 0 | I52: 4354374 | J52: VIETDT.HCM.NG | K52: 5 | L52: -4354374 | M52: FALSE | N52: -4354374_5 | O52: CHITIET51 | P52: 50
A53: 80100 | B53: 1 | C53: 1363111 | D53: Receivables-Misc Receipts | E53: TD - TCB - VTA | F53: TCBO202605270 | G53: 5097 | H53: 0 | I53: 3683392 | J53: VIETDT.HCM.NG | K53: 5 | L53: -3683392 | M53: FALSE | N53: -3683392_5 | O53: CHITIET52 | P53: 51
A54: 80100 | B54: 1 | C54: 1363111 | D54: Receivables-Misc Receipts | E54: TD - LVB - VTA | F54: LVBO202605250 | G54: 5108 | H54: 0 | I54: 3774535 | J54: VIETDT.HCM.NG | K54: 5 | L54: -3774535 | M54: FALSE | N54: -3774535_5 | O54: CHITIET53 | P54: 52
A55: 80100 | B55: 1 | C55: 1363111 | D55: Receivables-Misc Receipts | E55: TD - SCB - VTA | F55: SCBO202605260 | G55: 5109 | H55: 0 | I55: 3786340 | J55: VIETDT.HCM.NG | K55: 5 | L55: -3786340 | M55: FALSE | N55: -3786340_5 | O55: CHITIET54 | P55: 53
... A536: 82900 | B536: 2 | C536: 3363111 | D536: Receivables-Misc Receipts | E536: CTĐLVT chuyển tiền điện về TCT ĐL HCM qua NH BIDV | F536: R0526ĐTT0330 | G536: 1477 | H536: 4020393459 | I536: 0 | J536: CHAULTN.HCM.VTA | K536: 5 | L536: -4020393459 | M536: FALSE | N536: -4020393459_5 | O536: CHITIET535 | P536: 534
...

Sheet 1363112_3363112
A1: Madonvi | B1: NhomTK | C1: SoHieuTaiKhoan | D1: NGUON | E1: DienGiai | F1: SoCTPhanHePhu | G1: SoCTPhanHeGL | H1: SoPSNo | I1: SoPSCo | J1: NguoiLapCT | K1: Thang | L1: NET | M1: Trung | N1: VLOOKUP_NET | O1: id | P1: =HYPERLINK("#TONG_HOP!G1","TRO VE") -> TRO VE
A2: 80100 | B2: 1 | C2: 1363112 | D2: GL-MANUAL | E2: KC PTNB TIEN DIEN THANG 5-2026 - PCVT (VC) | G2: 5092 | H2: 0 | I2: 301236589 | J2: ANHTTL.HCM.NG | K2: 5 | L2: -301236589 | M2: FALSE | N2: -301236589_5 | O2: CHITIET1 | P2: 0
A3: 82900 | B3: 2 | C3: 3363112 | D3: GL-MANUAL | E3: Điều chỉnh tiền vô công chuyển về TCT ĐL HCM T05/2026 | G3: 1496 | H3: 0 | I3: 301236589 | J3: QUYENNN.HCM.VTA | K3: 5 | L3: 301236589 | M3: FALSE | N3: 301236589_5 | O3: CHITIET2 | P3: 1
A4: 82900 | B4: 2 | C4: 3363112 | D4: MassAllocation-Allocation | E4: K/c 51113 > 3363112 (k/c dthu công suất phản kháng) | G4: 1623 | H4: 0 | I4: 762611631 | J4: DUYENTT.HCM.VTA | K4: 5 | L4: 762611631 | M4: FALSE | N4: 762611631_5 | O4: CHITIET3 | P4: 2
A5: 82900 | B5: 2 | C5: 3363112 | D5: Receivables-Credit Memos | E5: Giải trừ tiền vô công thu hộ CTĐLVT ngày 22/05/2026 | F5: 1614 | G5: 1417 | H5: 18204661 | I5: 0 | J5: CHAULTN.HCM.VTA | K5: 5 | L5: -18204661 | M5: FALSE | N5: -18204661_5 | O5: CHITIET4 | P5: 3
A6: 82900 | B6: 2 | C6: 3363112 | D6: Receivables-Credit Memos | E6: Giải trừ tiền vô công thu hộ CTĐLVT ngày 09/05/2026 | F6: 1588 | G6: 1430 | H6: 22621067 | I6: 0 | J6: CHAULTN.HCM.VTA | K6: 5 | L6: -22621067 | M6: FALSE | N6: -22621067_5 | O6: CHITIET5 | P6: 4
A7: 82900 | B7: 2 | C7: 3363112 | D7: Receivables-Credit Memos | E7: Giải trừ tiền vô công thu hộ CTĐLVT ngày 18/05/2026 | F7: 1609 | G7: 1428 | H7: 24675649 | I7: 0 | J7: CHAULTN.HCM.VTA | K7: 5 | L7: -24675649 | M7: FALSE | N7: -24675649_5 | O7: CHITIET6 | P7: 5
A8: 82900 | B8: 2 | C8: 3363112 | D8: Receivables-Credit Memos | E8: Giải trừ tiền vô công thu hộ CTĐLVT ngày 05/05/2026 | F8: 1571 | G8: 1422 | H8: 29308455 | I8: 0 | J8: CHAULTN.HCM.VTA | K8: 5 | L8: -29308455 | M8: FALSE | N8: -29308455_5 | O8: CHITIET7 | P8: 6
A9: 82900 | B9: 2 | C9: 3363112 | D9: Receivables-Credit Memos | E9: Giải trừ tiền vô công thu hộ CTĐLVT ngày 06/05/2026 | F9: 1559 | G9: 1438 | H9: 75633744 | I9: 0 | J9: CHAULTN.HCM.VTA | K9: 5 | L9: -75633744 | M9: FALSE | N9: -75633744_5 | O9: CHITIET8 | P9: 7
A10: 82900 | B10: 2 | C10: 3363112 | D10: Receivables-Credit Memos | E10: Giải trừ tiền vô công thu hộ CTĐLVT ngày 04/05/2026 | F10: 1568 | G10: 1419 | H10: 121340050 | I10: 0 | J10: CHAULTN.HCM.VTA | K10: 5 | L10: -121340050 | M10: FALSE | N10: -121340050_5 | O10: CHITIET9 | P10: 8
A11: 82900 | B11: 2 | C11: 3363112 | D11: Receivables-Credit Memos | E11: Giải trừ tiền vô công thu hộ CTĐLVT ngày 11/05/2026 | F11: 1591 | G11: 1435 | H11: 1195232 | I11: 0 | J11: CHAULTN.HCM.VTA | K11: 5 | L11: -1195232 | M11: FALSE | N11: -1195232_5 | O11: CHITIET10 | P11: 9
A12: 82900 | B12: 2 | C12: 3363112 | D12: Receivables-Credit Memos | E12: Giải trừ tiền vô công thu hộ CTĐLVT ngày 13/05/2026 | F12: 1594 | G12: 1421 | H12: 3954874 | I12: 0 | J12: CHAULTN.HCM.VTA | K12: 5 | L12: -3954874 | M12: FALSE | N12: -3954874_5 | O12: CHITIET11 | P12: 10
A13: 82900 | B13: 2 | C13: 3363112 | D13: Receivables-Credit Memos | E13: Giải trừ tiền vô công thu hộ CTĐLVT ngày 08/05/2026 | F13: 1585 | G13: 1439 | H13: 10361251 | I13: 0 | J13: CHAULTN.HCM.VTA | K13: 5 | L13: -10361251 | M13: FALSE | N13: -10361251_5 | O13: CHITIET12 | P13: 11
A14: 82900 | B14: 2 | C14: 3363112 | D14: Receivables-Credit Memos | E14: Giải trừ tiền vô công thu hộ CTĐLVT ngày 26/05/2026 | F14: 1630 | G14: 1425 | H14: 11589615 | I14: 0 | J14: CHAULTN.HCM.VTA | K14: 5 | L14: -11589615 | M14: FALSE | N14: -11589615_5 | O14: CHITIET13 | P14: 12
A15: 82900 | B15: 2 | C15: 3363112 | D15: Receivables-Credit Memos | E15: Giải trừ tiền vô công thu hộ CTĐLVT ngày 16/05/2026 | F15: 1602 | G15: 1441 | H15: 12047809 | I15: 0 | J15: CHAULTN.HCM.VTA | K15: 5 | L15: -12047809 | M15: FALSE | N15: -12047809_5 | O15: CHITIET14 | P15: 13
A16: 82900 | B16: 2 | C16: 3363112 | D16: Receivables-Credit Memos | E16: Giải trừ tiền vô công thu hộ CTĐLVT ngày 14/05/2026 | F16: 1596 | G16: 1416 | H16: 13566695 | I16: 0 | J16: CHAULTN.HCM.VTA | K16: 5 | L16: -13566695 | M16: FALSE | N16: -13566695_5 | O16: CHITIET15 | P16: 14
... A18: 82900 | B18: 2 | C18: 3363112 | D18: Receivables-Credit Memos | E18: Giải trừ tiền vô công thu hộ CTĐLVT ngày 07/05/2026 | F18: 1582 | G18: 1420 | H18: 17562735 | I18: 0 | J18: CHAULTN.HCM.VTA | K18: 5 | L18: -17562735 | M18: FALSE | N18: -17562735_5 | O18: CHITIET17 | P18: 16
A19: 80100 | B19: 1 | C19: 1363112 | D19: Receivables-Misc Receipts | E19: VC - ABB - VTA | F19: ABBO202605061 | G19: 5106 | H19: 0 | I19: 11278650 | J19: VIETDT.HCM.NG | K19: 5 | L19: -11278650 | M19: FALSE | N19: -11278650_5 | O19: CHITIET18 | P19: 17
A20: 80100 | B20: 1 | C20: 1363112 | D20: Receivables-Misc Receipts | E20: VC - ABB - VTA | F20: ABBO202605161 | G20: 5118 | H20: 0 | I20: 11381580 | J20: VIETDT.HCM.NG | K20: 5 | L20: -11381580 | M20: FALSE | N20: -11381580_5 | O20: CHITIET19 | P20: 18
A21: 80100 | B21: 1 | C21: 1363112 | D21: Receivables-Misc Receipts | E21: VC - BIDV - VTA | F21: BIDVO202605031 | G21: 5113 | H21: 0 | I21: 11769401 | J21: VIETDT.HCM.NG | K21: 5 | L21: -11769401 | M21: FALSE | N21: -11769401_5 | O21: CHITIET20 | P21: 19
A22: 80100 | B22: 1 | C22: 1363112 | D22: Receivables-Misc Receipts | E22: VC - ICB - VTA | F22: ICBO202605071 | G22: 5112 | H22: 0 | I22: 11901571 | J22: VIETDT.HCM.NG | K22: 5 | L22: -11901571 | M22: FALSE | N22: -11901571_5 | O22: CHITIET21 | P22: 20
A23: 80100 | B23: 1 | C23: 1363112 | D23: Receivables-Misc Receipts | E23: VC - EXB - VTA | F23: EXBO202605031 | G23: 5113 | H23: 0 | I23: 12182159 | J23: VIETDT.HCM.NG | K23: 5 | L23: -12182159 | M23: FALSE | N23: -12182159_5 | O23: CHITIET22 | P23: 21
A24: 80100 | B24: 1 | C24: 1363112 | D24: Receivables-Misc Receipts | E24: VC - VCB - VTA | F24: VCBO202605051 | G24: 5117 | H24: 0 | I24: 12217266 | J24: VIETDT.HCM.NG | K24: 5 | L24: -12217266 | M24: FALSE | N24: -12217266_5 | O24: CHITIET23 | P24: 22
A25: 80100 | B25: 1 | C25: 1363112 | D25: Receivables-Misc Receipts | E25: VC - ICB - VTA | F25: ICBO202605141 | G25: 5096 | H25: 0 | I25: 13452674 | J25: VIETDT.HCM.NG | K25: 5 | L25: -13452674 | M25: FALSE | N25: -13452674_5 | O25: CHITIET24 | P25: 23
A26: 80100 | B26: 1 | C26: 1363112 | D26: Receivables-Misc Receipts | E26: VC - AGRI - VTA | F26: AGRIO202605051 | G26: 5117 | H26: 0 | I26: 14198403 | J26: VIETDT.HCM.NG | K26: 5 | L26: -14198403 | M26: FALSE | N26: -14198403_5 | O26: CHITIET25 | P26: 24
A27: 80100 | B27: 1 | C27: 1363112 | D27: Receivables-Misc Receipts | E27: VC - MBB - VTA | F27: MBBO202605091 | G27: 5102 | H27: 0 | I27: 19277739 | J27: VIETDT.HCM.NG | K27: 5 | L27: -19277739 | M27: FALSE | N27: -19277739_5 | O27: CHITIET26 | P27: 25
A28: 80100 | B28: 1 | C28: 1363112 | D28: Receivables-Misc Receipts | E28: VC - VCB - VTA | F28: VCBO202605061 | G28: 5106 | H28: 0 | I28: 33280661 | J28: VIETDT.HCM.NG | K28: 5 | L28: -33280661 | M28: FALSE | N28: -33280661_5 | O28: CHITIET27 | P28: 26
A29: 80100 | B29: 1 | C29: 1363112 | D29: Receivables-Misc Receipts | E29: VC - VCB - VTA | F29: VCBO202605041 | G29: 5107 | H29: 0 | I29: 53233830 | J29: VIETDT.HCM.NG | K29: 5 | L29: -53233830 | M29: FALSE | N29: -53233830_5 | O29: CHITIET28 | P29: 27
A30: 80100 | B30: 1 | C30: 1363112 | D30: Receivables-Misc Receipts | E30: VC - ACB - VTA | F30: ACBO202605041 | G30: 5107 | H30: 0 | I30: 23080 | J30: VIETDT.HCM.NG | K30: 5 | L30: -23080 | M30: FALSE | N30: -23080_5 | O30: CHITIET29 | P30: 28
... A86: 82900 | B86: 2 | C86: 3363112 | D86: Receivables-Misc Receipts | E86: CTĐLVT chuyển tiền vô công về TCT ĐL HCM qua NH BIDV | F86: R0526ĐTT0352A | G86: 1449 | H86: 692814920 | I86: 0 | J86: CHAULTN.HCM.VTA | K86: 5 | L86: -692814920 | M86: FALSE | N86: -692814920_5 | O86: CHITIET85 | P86: 84
A87: 80100 | B87: 1 | C87: 1363112 | D87: Receivables-Sales Invoices | E87: VNPay 18/05/2026 | F87: 42574 | G87: 5174 | H87: 0 | I87: 18498840 | J87: VIETDT.HCM.NG | K87: 5 | L87: -18498840 | M87: FALSE | N87: -18498840_5 | O87: CHITIET86 | P87: 85
A88: 80100 | B88: 1 | C88: 1363112 | D88: Receivables-Sales Invoices | E88: MService 09/05/2026 | F88: 42596 | G88: 5178 | H88: 0 | I88: 833117 | J88: VIETDT.HCM.NG | K88: 5 | L88: -833117 | M88: FALSE | N88: -833117_5 | O88: CHITIET87 | P88: 86
A89: 80100 | B89: 1 | C89: 1363112 | D89: Receivables-Sales Invoices | E89: MService 12/05/2026 | F89: 42599 | G89: 5170 | H89: 0 | I89: 2278237 | J89: VIETDT.HCM.NG | K89: 5 | L89: -2278237 | M89: FALSE | N89: -2278237_5 | O89: CHITIET88 | P89: 87
A90: 80100 | B90: 1 | C90: 1363112 | D90: Receivables-Sales Invoices | E90: VNPay 07/05/2026 | F90: 42563 | G90: 5176 | H90: 0 | I90: 703082 | J90: VIETDT.HCM.NG | K90: 5 | L90: -703082 | M90: FALSE | N90: -703082_5 | O90: CHITIET89 | P90: 88
A91: 80100 | B91: 1 | C91: 1363112 | D91: Receivables-Sales Invoices | E91: VNPay 05/05/2026 | F91: 42561 | G91: 5179 | H91: 0 | I91: 650252 | J91: VIETDT.HCM.NG | K91: 5 | L91: -650252 | M91: FALSE | N91: -650252_5 | O91: CHITIET90 | P91: 89
A92: 80100 | B92: 1 | C92: 1363112 | D92: Receivables-Sales Invoices | E92: VNPay 06/05/2026 | F92: 42562 | G92: 5182 | H92: 0 | I92: 7759801 | J92: VIETDT.HCM.NG | K92: 5 | L92: -7759801 | M92: FALSE | N92: -7759801_5 | O92: CHITIET91 | P92: 90
A93: 80100 | B93: 1 | C93: 1363112 | D93: Receivables-Sales Invoices | E93: ZaloPay 04/05/2026 | F93: 42449 | G93: 5172 | H93: 0 | I93: 1072524 | J93: VIETDT.HCM.NG | K93: 5 | L93: -1072524 | M93: FALSE | N93: -1072524_5 | O93: CHITIET92 | P93: 91
A94: 80100 | B94: 1 | C94: 1363112 | D94: Receivables-Sales Invoices | E94: MService 06/05/2026 | F94: 42593 | G94: 5182 | H94: 0 | I94: 564165 | J94: VIETDT.HCM.NG | K94: 5 | L94: -564165 | M94: FALSE | N94: -564165_5 | O94: CHITIET93 | P94: 92
A95: 80100 | B95: 1 | C95: 1363112 | D95: Receivables-Sales Invoices | E95: Payoo 10/05/2026 | F95: 42644 | G95: 5164 | H95: 0 | I95: 256319 | J95: VIETDT.HCM.NG | K95: 5 | L95: -256319 | M95: FALSE | N95: -256319_5 | O95: CHITIET94 | P95: 93
A96: 80100 | B96: 1 | C96: 1363112 | D96: Receivables-Sales Invoices | E96: MService 03/05/2026 | F96: 42590 | G96: 5177 | H96: 0 | I96: 145427 | J96: VIETDT.HCM.NG | K96: 5 | L96: -145427 | M96: FALSE | N96: -145427_5 | O96: CHITIET95 | P96: 94
...

Sheet 136312_336312
P1: =HYPERLINK("#TONG_HOP!G1","TRO VE") -> TRO VE
A6: Created with a trial version of Syncfusion Excel library or registered the wrong key in your application. Click here to obtain the valid key.

Sheet 136313_336313
P1: =HYPERLINK("#TONG_HOP!G1","TRO VE") -> TRO VE
A6: Created with a trial version of Syncfusion Excel library or registered the wrong key in your application. Click here to obtain the valid key.

Sheet 136314_336314
A1: Madonvi | B1: NhomTK | C1: SoHieuTaiKhoan | D1: NGUON | E1: DienGiai | F1: SoCTPhanHeGL | G1: SoPSNo | H1: SoPSCo | I1: NguoiLapCT | J1: Thang | K1: NET | L1: Trung | M1: VLOOKUP_NET | N1: id | O1: rowOrder | P1: =HYPERLINK("#TONG_HOP!G1","TRO VE") -> TRO VE
A2: 82900 | B2: 2 | C2: 336314 | D2: MassAllocation-Allocation | E2: K/c 5114 (QL dây, cáp) > 3363114 | F2: 1624 | G2: 0 | H2: 253573360 | I2: DUYENTT.HCM.VTA | J2: 5 | K2: 253573360 | L2: FALSE | M2: 253573360_5 | N2: CHITIET1 | O2: 0
A6: Created with a trial version of Syncfusion Excel library or registered the wrong key in your application. Click here to obtain the valid key.

Sheet 136315_336315
P1: =HYPERLINK("#TONG_HOP!G1","TRO VE") -> TRO VE
A6: Created with a trial version of Syncfusion Excel library or registered the wrong key in your application. Click here to obtain the valid key.

Sheet 136318_336318
P1: =HYPERLINK("#TONG_HOP!G1","TRO VE") -> TRO VE
A6: Created with a trial version of Syncfusion Excel library or registered the wrong key in your application. Click here to obtain the valid key.

Sheet 136321_336321
P1: =HYPERLINK("#TONG_HOP!G1","TRO VE") -> TRO VE
A6: Created with a trial version of Syncfusion Excel library or registered the wrong key in your application. Click here to obtain the valid key.

Sheet 136331_336331
A1: Madonvi | B1: NhomTK | C1: SoHieuTaiKhoan | D1: NGUON | E1: DienGiai | F1: SoCTPhanHePhu | G1: SoCTPhanHeGL | H1: SoPSNo | I1: SoPSCo | J1: NguoiLapCT | K1: Thang | L1: NET | M1: Trung | N1: VLOOKUP_NET | O1: id | P1: =HYPERLINK("#TONG_HOP!G1","TRO VE") -> TRO VE
A2: 82900 | B2: 2 | C2: 336331 | D2: GL-MANUAL | E2: Hạch toán giá trị TSCĐ nhận điều động nội bộ TCT tháng 05/2026 | G2: 1641 | H2: 0 | I2: 2534843522 | J2: HUONGDTT.HCM.VTA | K2: 5 | L2: 2534843522 | M2: FALSE | N2: 2534843522_5 | O2: CHITIET1 | P2: 0
A3: 82900 | B3: 2 | C3: 336331 | D3: GL-MANUAL | E3: Kết chuyển chi phí khấu hao T05/2026 | G3: 1643 | H3: 9176034319 | I3: 0 | J3: HUONGDTT.HCM.VTA | K3: 5 | L3: -9176034319 | M3: FALSE | N3: -9176034319_5 | O3: CHITIET2 | P3: 1
A4: 82900 | B4: 2 | C4: 336331 | D4: GL-MANUAL | E4: Kết chuyển giá trị PDQT theo QĐ 369/30.05.26 CT XDM, cải tạo lưới điện THT và TBA thị xã Phú Mỹ năm 2024_23009 | G4: 1355 | H4: 0 | I4: 4281150500 | J4: HUONGDTT.HCM.VTA | K4: 5 | L4: 4281150500 | M4: FALSE | N4: 4281150500_5 | O4: CHITIET3 | P4: 2
A5: 82900 | B5: 2 | C5: 336331 | D5: GL-MANUAL | E5: Kết chuyển giá trị PDQT theo QĐ 330/20.05.26 CT Đầu tư, cải tạo hệ thống AC/DC tại các trạm 110kv năm 2023_23018 | G5: 1355 | H5: 0 | I5: 3630279342 | J5: HUONGDTT.HCM.VTA | K5: 5 | L5: 3630279342 | M5: FALSE | N5: 3630279342_5 | O5: CHITIET4 | P5: 3
A6: 82900 | B6: 2 | C6: 336331 | D6: GL-PAYABLE-MANUAL | E6: Hạch toán cấp vốn trả lãi vay MB hợp đồng 268718 TB3038(CV xin vốn 2336) trả lãi vay CT22003 | G6: 1493 | H6: 0 | I6: 197460524 | J6: LINH3NTT.HCM.VTA | K6: 5 | L6: 197460524 | M6: FALSE | N6: 197460524_5 | O6: CHITIET5 | P6: 4
A7: 82900 | B7: 2 | C7: 336331 | D7: GL-PAYABLE-MANUAL | E7: Kết chuyển CT hoàn thành phê duyệt quyết toán CT23018 | G7: 1389 | H7: 3630279342 | I7: 0 | J7: HIENNTK.HCM.VTA | K7: 5 | L7: -3630279342 | M7: FALSE | N7: -3630279342_5 | O7: CHITIET6 | P7: 5
A8: 82900 | B8: 2 | C8: 336331 | D8: GL-PAYABLE-MANUAL | E8: Kết chuyển CT hoàn thành phê duyệt quyết toán CT23009 | G8: 1390 | H8: 4281150500 | I8: 0 | J8: HIENNTK.HCM.VTA | K8: 5 | L8: -4281150500 | M8: FALSE | N8: -4281150500_5 | O8: CHITIET7 | P8: 6
